<?xml version="1.0" ?>

<robot name ="my_rb1_robot">

<!-- Gazebo Colors-->
    <gazebo reference="base_link">
    <material>Gazebo/Black</material>
    </gazebo>

    <gazebo reference="link_right_wheel">
    <material>Gazebo/Red</material>
        <mu1>1</mu1>
        <mu2>1</mu2>
    </gazebo>

    <gazebo reference="link_left_wheel">
    <material>Gazebo/Red</material>
        <mu1>1</mu1>
        <mu2>1</mu2>
    </gazebo>

    <gazebo reference="front_caster">
        <material>Gazebo/Grey</material>
        <mu1>0</mu1>
        <mu2>0</mu2>
    </gazebo>

    <gazebo reference="back_caster">
        <material>Gazebo/Grey</material>
        <mu1>0</mu1>
        <mu2>0</mu2>
    </gazebo>

    <gazebo reference="front_laser">
        <material>Gazebo/DarkGrey</material>
    </gazebo>

    <gazebo reference="joint_base_bc_wheel">
        <preserveFixedJoint>true</preserveFixedJoint>
    </gazebo>

    <gazebo reference="joint_base_fc_wheel">
        <preserveFixedJoint>true</preserveFixedJoint>
    </gazebo>

    <gazebo reference="joint_base_fl">
        <preserveFixedJoint>true</preserveFixedJoint>
    </gazebo>
<!--Gazebo ros diff drive-->>
    <gazebo>
        <plugin filename="libgazebo_ros_diff_drive.so" name="differential_drive_controller">
            <alwaysOn>true</alwaysOn>
            <updateRate>20</updateRate>
            <leftJoint>joint_base_left_wheel</leftJoint>
            <rightJoint>joint_base_rigth_wheel</rightJoint>
            <wheelSeparation>0.4</wheelSeparation> <!--The distance of the left and right wheel(s). The diff_drive_controller will attempt to read the value from the URDF if this parameter is not specified -->>
            <wheelDiameter>0.05</wheelDiameter>
            <torque>10</torque>
            <commandTopic>cmd_vel</commandTopic>
            <odometryTopic>odom</odometryTopic>
            <odometryFrame>odom</odometryFrame>
            <robotBaseFrame>base_link</robotBaseFrame>
        </plugin>
    </gazebo>
<!--Gazebo Laser Scan-->>
    <gazebo reference="front_laser">
        <sensor type="ray" name="head_hokuyo_sensor">
            <pose>0 0 0 0 0 0</pose>
            <visualize>true</visualize>
            <update_rate>20</update_rate>
            <ray>
                <scan>
                    <horizontal>
                        <samples>720</samples>
                        <resolution>1</resolution>
                        <min_angle>-1.570796</min_angle>
                        <max_angle>1.570796</max_angle>
                    </horizontal>
                </scan>
                <range>
                    <min>0.05</min>
                    <max>5</max>
                    <resolution>0.01</resolution>
                </range>
                <noise>
                    <type>gaussian</type>
                    <mean>0.0</mean>
                    <stddev>0.01</stddev>
                </noise>
            </ray>
            <plugin name="gazebo_ros_head_hokuyo_controller" filename="libgazebo_ros_laser.so">
                <topicName>/scan</topicName>
                <frameName>sensor_laser</frameName>
            </plugin>
        </sensor>
    </gazebo>

<!-- URDF-->
    <link name = "base_footprint">
    </link>

    <!-- Joint base_footprint/base_link-->
    <joint name = "joint_bf_base_link" type = "fixed">
        <origin rpy = "0 0 0" xyz = "0 0 0.15"/>
        <child link = "base_link"/>
        <parent link = "base_footprint" />
    </joint>
    <!-- base link-->
    <link name = "base_link">
        <inertial>
            <mass value = "20"/>
            <origin xyz = "0 0 0" rpy = "0 0 0"/>
            <inertia 
                ixx ="0.4625"
                ixy ="0"
                ixz ="0"
                iyy ="0.4625"
                iyz ="0"
                izz ="0.625"
                />
        </inertial>

        <collision>
            <origin xyz = "0 0 0" rpy = "0 0 0"/>
            <geometry>
                <cylinder length = "0.03" radius= "0.025"/>
            </geometry>
        </collision>
        <visual>
            <origin xyz = "0 0 0" rpy = "0 0 0"/>
            <geometry>
                <cylinder length = "0.3" radius= "0.25"/>
            </geometry>
            <material name="Black">
                <color rgba="0.1 0.1 0.1 1" />
            </material>
        </visual>

    </link>
    <!-- joint base_link/right_wheel-->
    <joint name = "joint_base_rigth_wheel" type = "continuous">
        <origin rpy = "0 0 0" xyz = "0 0.2 -0.15"/>
        <child link = "link_right_wheel"/>
        <parent link = "base_link" />
        <axis rpy = "0 0 0" xyz = "0 1 0"/>
    </joint>
    <!-- joint base_link/left_wheel-->
    <joint name = "joint_base_left_wheel" type = "continuous">
        <origin rpy = "0 0 0" xyz = "0 -0.2 -0.15"/>
        <child link = "link_left_wheel"/>
        <parent link = "base_link" />
        <axis rpy = "0 0 0" xyz = "0 1 0"/>
    </joint>
    <!-- right wheel link-->
    <link name = "link_right_wheel">
            <inertial>
            <mass value = "1"/>
            <origin xyz = "0 0 0" rpy = "0 0 0"/>
            <inertia 
                ixx ="0.00023125"
                ixy ="0"
                ixz ="0"
                iyy ="0.00023125"
                iyz ="0"
                izz ="0.0003125"
                />
        </inertial>

        <collision>
            <origin xyz = "0 0 0" rpy = "1.57 0 0"/>
            <geometry>
                <cylinder length = "0.03" radius= "0.025"/>
            </geometry>
        </collision>
        <visual>
            <origin xyz = "0 0 0" rpy = "1.57 0 0"/>
            <geometry>
                <cylinder length = "0.03" radius= "0.025"/>
            </geometry>
        </visual>

    </link>
    <!-- left wheel link-->
    <link name = "link_left_wheel">
        <inertial>
            <mass value = "1"/>
            <origin xyz = "0 0 0" rpy = "0 0 0"/>
            <inertia 
            ixx ="0.00023125"
            ixy ="0"
            ixz ="0"
            iyy ="0.00023125"
            iyz ="0"
            izz ="0.0003125"
            />
        </inertial>

        <collision>
            <origin xyz = "0 0 0" rpy = "1.57 0 0"/>
            <geometry>
                <cylinder length = "0.03" radius= "0.025"/>
            </geometry>
        </collision>
        <visual>
            <origin xyz = "0 0 0" rpy = "1.57 0 0"/>
            <geometry>
                <cylinder length = "0.03" radius= "0.025"/>
            </geometry>
        </visual>

    </link>


    <!-- joint base_link/front_caster_wheel-->
    <joint name = "joint_base_fc_wheel" type = "fixed">
        <origin rpy = "0 0 0" xyz = "0.1 0.0 -0.15"/>
        <child link = "front_caster"/>
        <parent link = "base_link" />
        <axis rpy = "0 0 0" xyz = "0 1 0"/>
    </joint>
    <!-- joint base_link/back_caster_wheel-->
    <joint name = "joint_base_bc_wheel" type = "fixed">
        <origin rpy = "0 0 0" xyz = "-0.1 0.0 -0.15"/>
        <child link = "back_caster"/>
        <parent link = "base_link" />
        <axis rpy = "0 0 0" xyz = "0 1 0"/>
    </joint>

    <!-- front caster-->
    <link name = "front_caster">
            <inertial>
            <mass value = "1"/>
            <origin xyz = "0 0 0" rpy = "0 0 0"/>
            <inertia 
                ixx ="0.00025"
                ixy ="0"
                ixz ="0"
                iyy ="0.00025"
                iyz ="0"
                izz ="0.00025"
                />
        </inertial>
        <!-- caster support-->
        <collision>
            <origin xyz = "0 0 0.01" rpy = "0 0 0"/>
            <geometry>
                <sphere radius="0.025" />
            </geometry>
        </collision>
        <visual>
            <origin xyz = "0 0 0.01" rpy = "0 0 0"/>
            <geometry>
                <sphere radius="0.025" />
            </geometry>            
            <material name="DarkBlue">
                <color rgba="0.2 0.2 0.4 1" />
            </material>
        </visual>
        <!-- caster wheel-->
        <collision>
            <origin xyz = "0 0 -0.015" rpy = "0 0 0"/>
            <geometry>
                <sphere radius="0.01" />
            </geometry>
            <contact_coefficients mu="0.0" kp="0.0" kd="0.0" />
        </collision>
        <visual>
            <origin xyz = "0 0 -0.015" rpy = "0 0 0"/>
            <geometry>
                <sphere radius="0.01" />
            </geometry>
            <material name="Grey">
                <color rgba="0.6 0.6 0.6 1" />
            </material>
        </visual>
    </link>

    <!-- back caser link-->
    <link name = "back_caster">
            <inertial>
            <mass value = "1"/>
            <origin xyz = "0 0 0" rpy = "0 0 0"/>
            <inertia 
                ixx ="0.00025"
                ixy ="0"
                ixz ="0"
                iyy ="0.00025"
                iyz ="0"
                izz ="0.00025"
                />
        </inertial>
        <!-- caster support-->
        <collision>
            <origin xyz = "0 0 0.01" rpy = "0 0 0"/>
            <geometry>
                <sphere radius="0.025" />
            </geometry>
        </collision>
        <visual>
            <origin xyz = "0 0 0.01" rpy = "0 0 0"/>
            <geometry>
                <sphere radius="0.025" />
            </geometry>            
            <material name="DarkBlue">
                <color rgba="0.2 0.2 0.4 1" />
            </material>
        </visual>
        <!-- caster wheel-->
        <collision>
            <origin xyz = "0 0 -0.015" rpy = "0 0 0"/>
            <geometry>
                <sphere radius="0.01" />
            </geometry>
            <contact_coefficients mu="0.0" kp="0.0" kd="0.0" />
        </collision>
        <visual>
            <origin xyz = "0 0 -0.015" rpy = "0 0 0"/>
            <geometry>
                <sphere radius="0.01" />
            </geometry>
            <material name="Grey">
                <color rgba="0.6 0.6 0.6 1" />
            </material>
        </visual>
    </link>

    <!-- joint base_link/front_laser-->
    <joint name = "joint_base_fl" type = "fixed">
        <origin rpy = "3.14 0 0" xyz = "0.25 0.0 0.075"/>
        <child link = "front_laser"/>
        <parent link = "base_link" />
        <axis rpy = "0 0 0" xyz = "0 1 0"/>
    </joint>

    <!-- front laser link-->
    <link name = "front_laser">
            <inertial>
            <mass value = "1"/>
            <origin xyz = "0 0 0" rpy = "0 0 0"/>
            <inertia 
                ixx ="0.00023125"
                ixy ="0"
                ixz ="0"
                iyy ="0.00023125"
                iyz ="0"
                izz ="0.0003125"
                />
        </inertial>

        <collision>
            <origin xyz = "0 0 0" rpy = "1.57 0 0"/>
            <geometry>
                <cylinder length = "0.03" radius= "0.025"/>
            </geometry>
        </collision>
        <visual>
            <origin xyz = "0 0 0" rpy = "1.57 0 0"/>
            <geometry>
                <cylinder length = "0.03" radius= "0.025"/>
            </geometry>
        </visual>

    </link>

</robot>